Workbook
Name Brands: #REF!
Name Brands: #REF!
Name Destinations: #REF!
Name Destinations: #REF!
Name Funds: #REF!
Name Funds: #REF!

Sheet Invoice proposed format A
A1: Commercial Invoice
A2: Prog. No | B2: Style No | C2: Sample Ref | D2: Description | E2: ITEM | F2: HS CODE | G2: Colour | H2: Colour CODE | I2: PO No | J2: Carton QTY | K2: Quantity Pks | L2: Quantity Pcs | M2: Unit Price US$/Pc | N2: AMOUNT USD
A3: ETEX-35193 | B3: 9477005 | C3: NLJWFOR-0028 | D3: SS26 FJ RACER BODY | E3: LADIES BODYSUIT | F3: 61042900 | G3: BLACK | H3: 1 | I3: 3670521 | J3: ='Packing List proposed format A'!F13 -> 2 | L3: ='Packing List proposed format A'!H13 -> 200 | M3: 3.04 | N3: =L3*M3 -> 608 | O3: 3.04
A4: ETEX-35193 | B4: 9477005 | C4: NLJWFOR-0028 | D4: SS26 FJ RACER BODY | E4: LADIES BODYSUIT | F4: 61042900 | G4: WHITE | H4: 10 | I4: 3670519 | J4: ='Packing List proposed format A'!#REF! -> #REF! | L4: ='Packing List proposed format A'!#REF! -> #REF! | M4: 3.04 | N4: =L4*M4 -> #REF! | O4: 3.04

Sheet Packing List proposed format A
A1: PO NO | B1: =X1 -> 3670521 | C1: STL NO | D1: =Z1 -> 9477005 | E1: SAMPLE REF | F1: =AB1 -> NLJWFOR-0028 | G1: =AC1 -> ETEX-35193 | P1: Nt. Wt Per CTN | Q1: Gr. Wt Per CTN | R1: Total Nt. Wt | S1: Total Gr. Wt | W1: PO NO N | X1: 3670521 | Y1: STL NO | Z1: 9477005 | AA1: SAMPLE REF | AB1: NLJWFOR-0028 | AC1: ETEX-35193 | AD1: BLACK | AE1: 1
V2: PO NO | W2: =B1 -> 3670521
A3: Colour | B3: Code | C3: Size | D3: CTN no. | F3: CTN Qty | G3: Pcs/Ctn | H3: Total Pcs. | I3: SKU No | V3: SIZE-1 | W3: 4 | X3: 6 | Y3: 8 | Z3: 10 | AA3: 12 | AB3: 14 | AC3: 16 | AD3: 18 | AE3: 20 | AF3: 22 | AG3: 24 | AH3: 26 | AI3: 28 | AJ3: 30 | AK3: 32
A4: =AD1 -> BLACK | B4: =AE1 -> 1 | C4: 14 | D4: 1 | E4: =F4 -> 1 | F4: 1 | G4: 56 | H4: =F4*G4 -> 56 | I4: 9477034 | P4: =Q4-1.05 -> 9.75 | Q4: 10.8 | R4: =P4*F4 -> 9.75 | S4: =Q4*F4 -> 10.8 | T4: Ctn Measurement | X4: 9477030 | Y4: 9477033 | Z4: 9477028 | AA4: 9477031 | AB4: 9477034 | AC4: 9477036 | AD4: 9477027 | AE4: 9477029 | AF4: 9477032
A5: " | B5: " | C5: 16 | G5: 32 | H5: =G5 -> 32 | I5: 9477036 | T5: 59X29X33 | U5: =F13-U6 -> 0 | V5: =0.59*0.29*0.33*U5 -> 0 | W5: TOTAL | X5: =SUM(U5:U9) -> 2 | Y5: =SUM(V5:V9) -> 0.065018
A6: " | B6: " | C6: 20 | G6: 8 | H6: =G6 -> 8 | I6: 9477029 | T6: 59X29X19 | U6: 2 | V6: =0.59*0.29*0.19*U6 -> 0.065018
A7: " | B7: " | C7: 6 | D7: 2 | E7: 2 | F7: 1 | G7: 4 | H7: =F7*G7 -> 4 | I7: 9477030 | P7: =Q7-1.05 -> 10.35 | Q7: 11.4 | R7: =P7*F7 -> 10.35 | S7: =Q7*F7 -> 11.4 | T7: 59X29X23 | V7: =0.59*0.29*0.23*U7 -> 0
A8: " | B8: " | C8: 8 | G8: 6 | H8: =G8 -> 6 | I8: 9477033 | T8: 59X29X37 | V8: =0.59*0.29*0.37*U8 -> 0
A9: " | B9: " | C9: 10 | G9: 16 | H9: =G9 -> 16 | I9: 9477028 | T9: 59X29X29 | V9: =0.59*0.29*0.29*U9 -> 0
A10: " | B10: " | C10: 12 | G10: 46 | H10: =G10 -> 46 | I10: 9477031
A11: " | B11: " | C11: 18 | G11: 28 | H11: =G11 -> 28 | I11: 9477027
A12: " | B12: " | C12: 22 | G12: 4 | H12: =G12 -> 4 | I12: 9477032
A13: Total | C13: END | F13: =SUM(F4:F12) -> 2 | H13: =SUM(H4:H12) -> 200 | I13: KTSN | R13: =SUM(R4:R12) -> 20.1 | S13: =SUM(S4:S12) -> 22.2
B14: Net Wt: | C14: =R13 -> 20.1 | D14: Kgs | F14: Gr. Wt: | G14: =S13 -> 22.2 | H14: Kgs | I14: CBM | J14: =Y5 -> 0.065018 | W14: NORMAL

Sheet Packing List proposed format A2
A1: PO NO | B1: =X1 -> 3670519 | C1: STL NO | D1: =Z1 -> 9477005 | E1: SAMPLE REF | F1: =AB1 -> NLJWFOR-0028 | G1: =AC1 -> ETEX-35193 | P1: Nt. Wt Per CTN | Q1: Gr. Wt Per CTN | R1: Total Nt. Wt | S1: Total Gr. Wt | W1: PO NO N | X1: 3670519 | Y1: STL NO | Z1: 9477005 | AA1: SAMPLE REF | AB1: NLJWFOR-0028 | AC1: ETEX-35193 | AD1: WHITE | AE1: 10
V2: PO NO | W2: =B1 -> 3670519
A3: Colour | B3: Code | C3: Size | D3: CTN no. | F3: CTN Qty | G3: Pcs/Ctn | H3: Total Pcs. | I3: SKU No | V3: SIZE-1 | W3: 4 | X3: 6 | Y3: 8 | Z3: 10 | AA3: 12 | AB3: 14 | AC3: 16 | AD3: 18 | AE3: 20 | AF3: 22 | AG3: 24 | AH3: 26 | AI3: 28 | AJ3: 30 | AK3: 32
A4: =AD1 -> WHITE | B4: =AE1 -> 10 | C4: 14 | D4: 1 | E4: =F4 -> 1 | F4: 1 | G4: 70 | H4: =F4*G4 -> 70 | I4: 9477044 | P4: =Q4-1.05 -> 6.55 | Q4: 7.6 | R4: =P4*F4 -> 6.55 | S4: =Q4*F4 -> 7.6 | T4: Ctn Measurement | X4: 9477037 | Y4: 9477041 | Z4: 9477039 | AA4: 9477042 | AB4: 9477044 | AC4: 9477045 | AD4: 9477038 | AE4: 9477040 | AF4: 9477043
A5: " | B5: " | C5: 12 | D5: =E4+1 -> 2 | E5: =E4+F5 -> 2 | F5: 1 | G5: 58 | H5: =F5*G5 -> 58 | I5: 9477042 | P5: =Q5-1.05 -> 9.15 | Q5: 10.2 | R5: =P5*F5 -> 9.15 | S5: =Q5*F5 -> 10.2 | T5: 59X29X33 | U5: =F13-U6 -> 0 | V5: =0.59*0.29*0.33*U5 -> 0 | W5: TOTAL | X5: =SUM(U5:U9) -> 3 | Y5: =SUM(V5:V9) -> 0.097527
A6: " | B6: " | C6: 16 | G6: 40 | H6: =G6 -> 40 | I6: 9477045 | T6: 59X29X19 | U6: 3 | V6: =0.59*0.29*0.19*U6 -> 0.097527
A7: " | B7: " | C7: 6 | D7: 3 | E7: 3 | F7: 1 | G7: 5 | H7: =F7*G7 -> 5 | I7: 9477037 | P7: =Q7-1.05 -> 8.55 | Q7: 9.6 | R7: =P7*F7 -> 8.55 | S7: =Q7*F7 -> 9.6 | T7: 59X29X23 | V7: =0.59*0.29*0.23*U7 -> 0
A8: " | B8: " | C8: 8 | G8: 8 | H8: =G8 -> 8 | I8: 9477041 | T8: 59X29X37 | V8: =0.59*0.29*0.37*U8 -> 0
A9: " | B9: " | C9: 10 | G9: 20 | H9: =G9 -> 20 | I9: 9477039 | T9: 59X29X29 | V9: =0.59*0.29*0.29*U9 -> 0
A10: " | B10: " | C10: 18 | G10: 35 | H10: =G10 -> 35 | I10: 9477038
A11: " | B11: " | C11: 20 | G11: 10 | H11: =G11 -> 10 | I11: 9477040
A12: " | B12: " | C12: 22 | G12: 5 | H12: =G12 -> 5 | I12: 9477043
A13: Total | C13: END | F13: =SUM(F4:F12) -> 3 | H13: =SUM(H4:H12) -> 251 | I13: KTSN | R13: =SUM(R4:R12) -> 24.25 | S13: =SUM(S4:S12) -> 27.4
B14: Net Wt: | C14: =R13 -> 24.25 | D14: Kgs | F14: Gr. Wt: | G14: =S13 -> 27.4 | H14: Kgs | I14: CBM | J14: =Y5 -> 0.097527 | W14: NORMAL

Sheet Invoice proposed format B
A1: Commercial Invoice
A2: Prog. No | B2: Style No | C2: Sample Ref | D2: Description | E2: ITEM | F2: HS CODE | G2: Colour | H2: Colour CODE | I2: PO No | J2: Carton QTY | K2: Quantity Pks | L2: Quantity Pcs | M2: Unit Price US$/Pc | N2: AMOUNT USD
A3: ETEX-35193 | B3: 9477005 | C3: NLJWFOR-0028 | D3: SS26 FJ RACER BODY | E3: LADIES BODYSUIT | F3: 61042900 | G3: BLACK | H3: 1 | I3: 3670521 | J3: ='Packing List proposed format B'!#REF! -> #REF! | L3: ='Packing List proposed format B'!#REF! -> #REF! | M3: 3.04 | N3: =L3*M3 -> #REF! | O3: 3.04
A4: ETEX-35193 | B4: 9477005 | C4: NLJWFOR-0028 | D4: SS26 FJ RACER BODY | E4: LADIES BODYSUIT | F4: 61042900 | G4: WHITE | H4: 10 | I4: 3670519 | J4: ='Packing List proposed format B'!#REF! -> #REF! | L4: ='Packing List proposed format B'!#REF! -> #REF! | M4: 3.04 | N4: =L4*M4 -> #REF! | O4: 3.04

Sheet Packing List proposed format B
A1: PO NO | B1: STL NO | C1: SAMPLE REF | D1: JWP | E1: Colour | F1: Code | G1: Size | H1: CTN no. | J1: CTN Qty | K1: Pcs/Ctn | L1: Total Pcs. | M1: SKU No
A2: 3670521 | B2: 9477005 | C2: NLJWFOR-0028 | D2: ETEX-35193 | E2: =#REF! -> #REF! | F2: =#REF! -> #REF! | G2: 14 | H2: 1 | I2: =J2 -> 1 | J2: 1 | K2: 56 | L2: =J2*K2 -> 56 | M2: 9477034
A3: 3670521 | B3: 9477005 | C3: NLJWFOR-0028 | D3: ETEX-35193 | E3: " | F3: " | G3: 16 | K3: 32 | L3: =K3 -> 32 | M3: 9477036
A4: 3670521 | B4: 9477005 | C4: NLJWFOR-0028 | D4: ETEX-35193 | E4: " | F4: " | G4: 20 | K4: 8 | L4: =K4 -> 8 | M4: 9477029
A5: 3670521 | B5: 9477005 | C5: NLJWFOR-0028 | D5: ETEX-35193 | E5: " | F5: " | G5: 6 | H5: 2 | I5: 2 | J5: 1 | K5: 4 | L5: =J5*K5 -> 4 | M5: 9477030
A6: 3670521 | B6: 9477005 | C6: NLJWFOR-0028 | D6: ETEX-35193 | E6: " | F6: " | G6: 8 | K6: 6 | L6: =K6 -> 6 | M6: 9477033
A7: 3670521 | B7: 9477005 | C7: NLJWFOR-0028 | D7: ETEX-35193 | E7: " | F7: " | G7: 10 | K7: 16 | L7: =K7 -> 16 | M7: 9477028
A8: 3670521 | B8: 9477005 | C8: NLJWFOR-0028 | D8: ETEX-35193 | E8: " | F8: " | G8: 12 | K8: 46 | L8: =K8 -> 46 | M8: 9477031
A9: 3670521 | B9: 9477005 | C9: NLJWFOR-0028 | D9: ETEX-35193 | E9: " | F9: " | G9: 18 | K9: 28 | L9: =K9 -> 28 | M9: 9477027
A10: 3670521 | B10: 9477005 | C10: NLJWFOR-0028 | D10: ETEX-35193 | E10: " | F10: " | G10: 22 | K10: 4 | L10: =K10 -> 4 | M10: 9477032
A15: PO NO | B15: STL NO | C15: SAMPLE REF | D15: JWP | E15: Colour | F15: Code | G15: Size | H15: CTN no. | J15: CTN Qty | K15: Pcs/Ctn | L15: Total Pcs. | M15: SKU No
A16: 3670519 | B16: 9477005 | C16: NLJWFOR-0028 | D16: ETEX-35193 | E16: =#REF! -> #REF! | F16: =#REF! -> #REF! | G16: 14 | H16: 1 | I16: =J16 -> 1 | J16: 1 | K16: 70 | L16: =J16*K16 -> 70 | M16: 9477044
A17: 3670519 | B17: 9477005 | C17: NLJWFOR-0028 | D17: ETEX-35193 | E17: " | F17: " | G17: 12 | H17: =I16+1 -> 2 | I17: =I16+J17 -> 2 | J17: 1 | K17: 58 | L17: =J17*K17 -> 58 | M17: 9477042
A18: 3670519 | B18: 9477005 | C18: NLJWFOR-0028 | D18: ETEX-35193 | E18: " | F18: " | G18: 16 | K18: 40 | L18: =K18 -> 40 | M18: 9477045
A19: 3670519 | B19: 9477005 | C19: NLJWFOR-0028 | D19: ETEX-35193 | E19: " | F19: " | G19: 6 | H19: 3 | I19: 3 | J19: 1 | K19: 5 | L19: =J19*K19 -> 5 | M19: 9477037
A20: 3670519 | B20: 9477005 | C20: NLJWFOR-0028 | D20: ETEX-35193 | E20: " | F20: " | G20: 8 | K20: 8 | L20: =K20 -> 8 | M20: 9477041
A21: 3670519 | B21: 9477005 | C21: NLJWFOR-0028 | D21: ETEX-35193 | E21: " | F21: " | G21: 10 | K21: 20 | L21: =K21 -> 20 | M21: 9477039
A22: 3670519 | B22: 9477005 | C22: NLJWFOR-0028 | D22: ETEX-35193 | E22: " | F22: " | G22: 18 | K22: 35 | L22: =K22 -> 35 | M22: 9477038
A23: 3670519 | B23: 9477005 | C23: NLJWFOR-0028 | D23: ETEX-35193 | E23: " | F23: " | G23: 20 | K23: 10 | L23: =K23 -> 10 | M23: 9477040
A24: 3670519 | B24: 9477005 | C24: NLJWFOR-0028 | D24: ETEX-35193 | E24: " | F24: " | G24: 22 | K24: 5 | L24: =K24 -> 5 | M24: 9477043

Sheet Invoice
A1: Commercial Invoice
A2: Invoice No. | B2: 106725 | H2: EXP NO. 2486-031981-2026 | N2: KNIT
A3: Date: 20/04/2026 | H3: =A3 -> Date: 20/04/2026
A4: Consignee : To the order of | H4: Contract No. ETL/ESL/ALL/745/2024
A5: New Look Retailers Ltd. | H5: Date: 26/08/2024
A6: Mercery Road, Weymouth, Dorset, DT3 5HJ, UK. | H6: Shipping Marks:
H7: ECHO-NewLook
H8: P O Number
H9: Style No
H10: Size
H11: Colour
H12: Carton Number
H13: Cartons
H15: Side Marks:
H16: Carton Measurement:
H17: Net Weight: Kgs
H18: Gross Weight: Kgs
A19: Notify :
A20: 1. Echo Sourcing Limited | H20: ERC No. RA-0086286
A21: 110-112 Parkway, Camden, | H21: Date: 30.01.2008
A22: London, NW1 7AN, UK | H22: Number of Registered Exporter: BDREX00955
A23: 2. New Look Retailers Ltd.
A24: Mercery Road, Weymouth, Dorset, DT3 5HJ, UK. | H24: Incoterm: CPT | K24: HWBL No.:
A25: Buyer Bank: | B25: HSBC UK BANK PLC, | H25: Shipment: By Air | K25: Date:
A26: GLOBAL TRADE SOLUTIONS, | H26: From : Dhaka Airport, Bangladesh
A27: 1ST FLOOR, 5 WESTERN BOULEVARD, BEDE ISLAND, LEICESTER, LE2 7EX | H27: To: LHR.
A28: SUPPLIER REF # 1482
A29: Prog. No | B29: Style No | C29: Sample Ref | D29: Description | E29: ITEM | F29: HS CODE | G29: Colour | H29: Colour CODE | I29: PO No | J29: Carton QTY | K29: Quantity Pks | L29: Quantity Pcs | M29: Unit Price US$/Pc | N29: AMOUNT USD
A30: ETEX-35193 | B30: 9477005 | C30: NLJWFOR-0028 | D30: SS26 FJ RACER BODY | E30: LADIES BODYSUIT | F30: 61042900 | G30: BLACK | H30: 1 | I30: 3670521 | J30: ='Packing List'!F40 -> 2 | L30: ='Packing List'!H40 -> 200 | M30: 3.04 | N30: =L30*M30 -> 608 | O30: 3.04
A31: ETEX-35193 | B31: 9477005 | C31: NLJWFOR-0028 | D31: SS26 FJ RACER BODY | E31: LADIES BODYSUIT | F31: 61042900 | G31: WHITE | H31: 10 | I31: 3670519 | J31: ='Packing List'!F56 -> 3 | L31: ='Packing List'!H56 -> 251 | M31: 3.04 | N31: =L31*M31 -> 763.04 | O31: 3.04
A33: TOTAL | J33: =SUM(J30:J32) -> 5 | L33: =SUM(L30:L32) -> 451 | N33: =SUM(N30:N32) -> 1371.04
A35: The exporter of the products covered by this document Echotex Ltd 000368453-0103 by request of NEW LOOK declares that, except where otherwise clearly indicated, these products are of Bangladesh preferential origin in accordance with the rules of origin of the Developing Countries Trading Scheme of the UK and that the origin criterion met is W 6104
A36: The exporter ECHOTEX LIMITED, REX- BDREX00955 of the products covered by this document declares that, except where otherwise clearly indicated, these Products are of Bangaladesh preferential origin according to rules of origin of the Generalized System of Preferences of the EU and that the origin criterion met is "W" 6104
A38: Total Qty : | C38: ='Packing List'!B63 -> 451 | D38: Pcs
A39: Total Carton: | C39: ='Packing List'!B64 -> 5 | D39: Ctns | S39: =2883-2853.47 -> 29.53
A40: Net Weight : | C40: ='Packing List'!B65 -> 44.35 | D40: Kgs
A41: Gross Weight: | C41: ='Packing List'!B66 -> 49.6 | D41: Kgs
A42: CBM | C42: ='Packing List'!B67 -> 0.162545
A43: ='Packing List'!A68 -> Carton Measurement : 59x29x33 CM. | D43: ='Packing List'!D68 -> 0
A44: ='Packing List'!A69 -> Carton Measurement : 59x29x19 CM. | D44: ='Packing List'!D69 -> 5
...

Sheet Packing List
A1: Packing List
A2: =Invoice!A2 -> Invoice No. | B2: =Invoice!B2 -> 106725 | H2: =Invoice!H4 -> Contract No. ETL/ESL/ALL/745/2024
A3: =Invoice!A3 -> Date: 20/04/2026 | H3: =Invoice!H5 -> Date: 26/08/2024
A4: Consignee : To the order of | H4: Shipping Marks:
A5: New Look Retailers Ltd. | H5: ECHO-NewLook
A6: Mercery Road, Weymouth, Dorset, DT3 5HJ, UK. | H6: P O Number
H7: Style No
H8: Size
H9: Colour
H10: Carton Number
H11: Cartons
H12: Side Marks:
H13: Carton Measurement:
H14: Net Weight: Kgs
H15: Gross Weight: Kgs
H18: ERC No. RA-0086286
A19: Notify : | H19: Date: 30.01.2008
A20: 1. Echo Sourcing Limited
A21: 110-112 Parkway, Camden, | H21: =Invoice!H24 -> Incoterm: CPT
A22: London, NW1 7AN, UK | H22: =Invoice!H25 -> Shipment: By Air
A23: 2. New Look Retailers Ltd. | H23: =Invoice!H26 -> From : Dhaka Airport, Bangladesh
A24: Mercery Road, Weymouth, Dorset, DT3 5HJ, UK. | H24: =Invoice!H27 -> To: LHR.
A26: Description of Goods: as per invoice
A28: PO NO | B28: =X28 -> 3670521 | C28: STL NO | D28: =Z28 -> 9477005 | E28: SAMPLE REF | F28: =AB28 -> NLJWFOR-0028 | G28: =AC28 -> ETEX-35193 | P28: Nt. Wt Per CTN | Q28: Gr. Wt Per CTN | R28: Total Nt. Wt | S28: Total Gr. Wt | W28: PO NO N | X28: 3670521 | Y28: STL NO | Z28: 9477005 | AA28: SAMPLE REF | AB28: NLJWFOR-0028 | AC28: ETEX-35193 | AD28: BLACK | AE28: 1
V29: PO NO | W29: =B28 -> 3670521
A30: Colour | B30: Code | C30: Size | D30: CTN no. | F30: CTN Qty | G30: Pcs/Ctn | H30: Total Pcs. | I30: SKU No | V30: SIZE-1 | W30: 4 | X30: 6 | Y30: 8 | Z30: 10 | AA30: 12 | AB30: 14 | AC30: 16 | AD30: 18 | AE30: 20 | AF30: 22 | AG30: 24 | AH30: 26 | AI30: 28 | AJ30: 30 | AK30: 32
A31: =AD28 -> BLACK | B31: =AE28 -> 1 | C31: 14 | D31: 1 | E31: =F31 -> 1 | F31: 1 | G31: 56 | H31: =F31*G31 -> 56 | I31: 9477034 | P31: =Q31-1.05 -> 9.75 | Q31: 10.8 | R31: =P31*F31 -> 9.75 | S31: =Q31*F31 -> 10.8 | T31: Ctn Measurement | X31: 9477030 | Y31: 9477033 | Z31: 9477028 | AA31: 9477031 | AB31: 9477034 | AC31: 9477036 | AD31: 9477027 | AE31: 9477029 | AF31: 9477032
A32: " | B32: " | C32: 16 | G32: 32 | H32: =G32 -> 32 | I32: 9477036 | T32: 59X29X33 | U32: =F40-U33 -> 0 | V32: =0.59*0.29*0.33*U32 -> 0 | W32: TOTAL | X32: =SUM(U32:U36) -> 2 | Y32: =SUM(V32:V36) -> 0.065018
A33: " | B33: " | C33: 20 | G33: 8 | H33: =G33 -> 8 | I33: 9477029 | T33: 59X29X19 | U33: 2 | V33: =0.59*0.29*0.19*U33 -> 0.065018
A34: " | B34: " | C34: 6 | D34: 2 | E34: 2 | F34: 1 | G34: 4 | H34: =F34*G34 -> 4 | I34: 9477030 | P34: =Q34-1.05 -> 10.35 | Q34: 11.4 | R34: =P34*F34 -> 10.35 | S34: =Q34*F34 -> 11.4 | T34: 59X29X23 | V34: =0.59*0.29*0.23*U34 -> 0
A35: " | B35: " | C35: 8 | G35: 6 | H35: =G35 -> 6 | I35: 9477033 | T35: 59X29X37 | V35: =0.59*0.29*0.37*U35 -> 0
A36: " | B36: " | C36: 10 | G36: 16 | H36: =G36 -> 16 | I36: 9477028 | T36: 59X29X29 | V36: =0.59*0.29*0.29*U36 -> 0
A37: " | B37: " | C37: 12 | G37: 46 | H37: =G37 -> 46 | I37: 9477031
A38: " | B38: " | C38: 18 | G38: 28 | H38: =G38 -> 28 | I38: 9477027
A39: " | B39: " | C39: 22 | G39: 4 | H39: =G39 -> 4 | I39: 9477032
A40: Total | C40: END | F40: =SUM(F31:F39) -> 2 | H40: =SUM(H31:H39) -> 200 | I40: KTSN | R40: =SUM(R31:R39) -> 20.1 | S40: =SUM(S31:S39) -> 22.2
B41: Net Wt: | C41: =R40 -> 20.1 | D41: Kgs | F41: Gr. Wt: | G41: =S40 -> 22.2 | H41: Kgs | I41: CBM | J41: =Y32 -> 0.065018 | W41: NORMAL
A44: PO NO | B44: =X44 -> 3670519 | C44: STL NO | D44: =Z44 -> 9477005 | E44: SAMPLE REF | F44: =AB44 -> NLJWFOR-0028 | G44: =AC44 -> ETEX-35193 | P44: Nt. Wt Per CTN | Q44: Gr. Wt Per CTN | R44: Total Nt. Wt | S44: Total Gr. Wt | W44: PO NO N | X44: 3670519 | Y44: STL NO | Z44: 9477005 | AA44: SAMPLE REF | AB44: NLJWFOR-0028 | AC44: ETEX-35193 | AD44: WHITE | AE44: 10
V45: PO NO | W45: =B44 -> 3670519
A46: Colour | B46: Code | C46: Size | D46: CTN no. | F46: CTN Qty | G46: Pcs/Ctn | H46: Total Pcs. | I46: SKU No | V46: SIZE-1 | W46: 4 | X46: 6 | Y46: 8 | Z46: 10 | AA46: 12 | AB46: 14 | AC46: 16 | AD46: 18 | AE46: 20 | AF46: 22 | AG46: 24 | AH46: 26 | AI46: 28 | AJ46: 30 | AK46: 32
...

Sheet VGM
B7: Verified Gross Mass (VGM) Statement
A10: Please type in all details in CAPITAL LETTERS; no handwriting. Items marked with * are mandatory.
A11: Shipper company name* | D11: ECHOTEX LIMITED | G11: Submission date*
A12: Address* | D12: CHANDRA (POLLI BIDDUT), MOUCHAK, KALIAKOIR, GAZIPUR, BANGLADESH
A13: Authorized VGM contact* | D13: MD. JAKIR HOSSAIN | G13: Signature of authorized contact*
A14: Phone number | D14: 01779 471806
A15: Fax number | D15: (06822) 51876
A16: E-mail address | D16: jakir@echotexbd.com
A19: Consignee | D19: NEW LOOK
A20: Shipper invoice number * | D20: =Invoice!B2 -> 106725 | G20: Place of receipt
A21: P/O number | G21: Place of departure
A22: Vessel name | G22: Place of discharge
A23: Voyage number | G23: Final destination
A24: ETD/ETA | G24: Freight terms
A26: Container No | G26: Verified gross mass (VGM)
A27: Number and kind of Pkg* | D27: =Invoice!C39 -> 5 | E27: CTN | G27: in kilograms* | I27: =Invoice!C41 -> 49.6 | J27: KGS
A28: Description of goods | D28: T-SHIRT
A30: The duly authorized contact person of the shipper (by name and signature provided in the statement) hereby certifies that the above mentioned shipment details have been evaluated carefully and according to the requirements of the International Convention for the Safety of Life at Sea (SOLAS); as they have been published in Chapter VI, Part A, Regulation 2 – Cargo Information.
A35: We understand and confirm that missing, incorrect and/or belated VGM statements may result in non-acceptance of the shipment by the vessel operating ocean carriers and a delay in the originally planned schedule. Any additional cost caused by delay due to non-acceptance of the shipment by the carrier to be covered by VGM declaring part (as undersigned above).

Sheet Draft
B2: Shipper | C2: Notify
B3: ECHOTEX LIMITED HEAD OFFICE: HOUSE # 139, LANE # 04, NEW DOHS, MOHAKHALI, DHAKA-1206. FACTORY: CHANDRA (POLLI BIDDUT), MOUCHAK, KALIAKOIR, GAZIPUR, BANGLADESH. | C3: ECHO SOURCING LIMITED 110-112 PARKWAY, CAMDEN, LONDON, NW1 7AN, UK.
B5: Consignee | C5: Also Notify
B6: TO THE ORDER OF STANDARD CHARTERED BANK TRADE SERVICES- DHAKA, 67 GULSHAN AVENUE, DHAKA-1212, BANGLADESH. | C6: NEW LOOK REATAILERS LTD. MERCERY ROAD, WEYMOUTH, DOREST, DT3 5HJ, UK.
B8: Shipping Mark | C8: Description of goods
B9: ECHO-NEW LOOK PO NUMBER STYLE NO SIZE COLOUR CARTON NUMBER CARTONS | C9: 319 CTN DESCRIPTION OF GOODS: AS PER COMMERCIAL INVOICE PO NO: 3411176, 3411112, 3411113, 3411115, 3411206, 3411116, 3411131, 3411133, 3415481, 3411231, 3423606, 3415511, 3415660, 3427573, 3427565, 3427570 HS CODE: 6109.10.00 INVOICE NO: ETEX-18026NL/23 DATE: 30.01.2023 EXP NO: 2486-0099395-2023 DATE: 30.01.2023 CONTRACT NO: ECHOTEX/ECHO/NL/694/2021 DATE: 28.11.2021 SHIPPING BILL NO. C 177509 DT. 30.01.2023

Sheet CIF
F1: =Invoice!#REF! -> #REF!
A3: Data Table
A4: No | B4: Word 1 | C4: Word 2 | D4: Word 3 | E4: Word 4 | F4: Word 5
A5: 0
A6: 1 | B6: One | C6: One Hundred | D6: One Thousand | E6: One Million | F6: And Cents One
A7: 2 | B7: Two | C7: Two Hundred | D7: Two Thousand | E7: Two Million | F7: And Cents Two
A8: 3 | B8: Three | C8: Three Hundred | D8: Three Thousand | E8: Three Million | F8: And Cents Three
A9: 4 | B9: Four | C9: Four Hundred | D9: Four Thousand | E9: Four Million | F9: And Cents Four
A10: 5 | B10: Five | C10: Five Hundred | D10: Five Thousand | E10: Five Million | F10: And Cents Five
A11: 6 | B11: Six | C11: Six Hundred | D11: Six Thousand | E11: Six Million | F11: And Cents Six
A12: 7 | B12: Seven | C12: Seven Hundred | D12: Seven Thousand | E12: Seven Million | F12: And Cents Seven
A13: 8 | B13: Eight | C13: Eight Hundred | D13: Eight Thousand | E13: Eight Million | F13: And Cents Eight
A14: 9 | B14: Nine | C14: Nine Hundred | D14: Nine Thousand | E14: Nine Million | F14: And Cents Nine
A15: 10 | B15: Ten | C15: Ten Hundred | D15: Ten Thousand | E15: Ten Million | F15: And Cents Ten
A16: 11 | B16: Eleven | C16: Eleven Hundred | D16: Eleven Thousand | E16: Eleven Million | F16: And Cents Eleven
A17: 12 | B17: Twelve | C17: Twelve Hundred | D17: Twelve Thousand | E17: Twelve Million | F17: And Cents Twelve
... A104: 99 | B104: Ninety Nine | C104: Ninety Nine Hundred | D104: Ninety Nine Thousand | E104: Ninety Nine Million | F104: And Cents Ninety Nine
A106: Amount | E106: =+F1 -> #REF!
A107: Text Figure | E107: =TEXT(E106*100,"00000000000") -> #REF!
A108: Words | B108: =UPPER(CONCATENATE("US DOLLARS",C112,C113,C114,C115,C116,C117,C118,C120,"Only.")) -> #REF!
A110: ** Janet, the maximum amount is 99,999,999.00
A112: Million | B112: =VALUE(LEFT(E107,3)) -> #REF! | C112: =VLOOKUP(B112,A4:F104,5,FALSE) -> #REF!
A113: Hundred Thousand | B113: =VALUE(MID(E107,4,1)) -> #REF! | C113: =VLOOKUP(B113,A4:E104,3,FALSE) -> #REF!
A114: Thousand | B114: =VALUE(MID(E107,5,2)) -> #REF! | C114: =IF(B114>0,VLOOKUP(B114,A4:E104,4,FALSE),IF(B113>0,"Thousand ","")) -> #REF!
C115: =IF(B114+B113<1,"",IF(B118+B120>0,"",IF(B116>0,"And ",""))) -> #REF!
A116: Hundred | B116: =VALUE(MID(E107,7,1)) -> #REF! | C116: =IF(B116<1,"",VLOOKUP(B116,A4:E104,3,FALSE)) -> #REF!
C117: =IF(B120>0,"",IF(B118<1,"",IF(B113+B114+B116=0,"","And "))) -> #REF!
A118: Ten | B118: =VALUE(MID(E107,8,2)) -> #REF! | C118: =IF(B118<1,"",VLOOKUP(B118,A4:$E104,2,FALSE)) -> #REF!
A120: Cents | B120: =VALUE(RIGHT(E107,2)) -> #REF! | C120: =IF(B120<1,"",VLOOKUP(B120,A4:F104,6,FALSE)) -> #REF!
B121: /th
